Workbook

Sheet 00_Inputs
A1: POWERLOGIC BESS · INDIAN POWER MARKET
A2: Industrial BESS Model — MSEDCL (Maharashtra) — all-formula workbook
A3: Legend: blue = input you edit · yellow = key levers · black = formula · green = link to another sheet.
A4: Mirrors github.com/jai2k701/powerlogic-bess (Modules 00 sizing · 01 dispatch · 02 revenue).
A6: MARKET
A7: Price day (1=Typical, 2=Summer, 3=Monsoon) | B7: 1 | C7: =INDEX(Prices!$B$1:$D$1,1,B7) -> Typical day (DAM) | D7: Representative IEX DAM shapes on the Prices sheet — assumptions, not live data
A8: BATTERY
A9: Power — manual (MW) | B9: 10
A10: Energy — manual (MWh) | B10: 20
A11: Use Module-00 suggested size? (1=yes, 0=manual) | B11: 1 | D11: 1 → dispatch & revenue take P/E from the 01_Sizing sheet
A12: Round-trip efficiency | B12: 0.88 | D12: Losses applied on discharge
A13: Power used by model (MW) | B13: =IF('00_Inputs'!$B$11=1,'01_Sizing'!$C$9,'00_Inputs'!$B$9) -> 7.5 | D13: Feeds 02_Dispatch and 03_Revenue
A14: Energy used by model (MWh) | B14: =IF('00_Inputs'!$B$11=1,'01_Sizing'!$C$13,'00_Inputs'!$B$10) -> 75.239424 | D14: Installed (container-rounded) energy when the switch is 1
A15: MSEDCL TARIFF — HT INDUSTRIAL (FY2026-27 ORDER)
A16: Base energy charge (₹/kWh) | B16: 8.44 | D16: Source: MSEDCL tariff order via powerlogic DB (user)
A17: ToD peak multiplier (17:00–24:00) | B17: 1.2
A18: ToD solar multiplier (09:00–17:00) | B18: 0.85 | D18: Apr–Sep −15%; set 0.75 for Oct–Mar (−25%)
A19: Open-access adders (₹/kWh) | B19: 3.65 | D19: 33 kV: STU 0.52 + wheeling 0.81 + CSS 2.07 + green cess 0.25. 132/220 kV ≈ 2.84. 7.5% wheeling loss in kind not modelled
A20: Peak tariff (₹/kWh) | B20: ='00_Inputs'!$B$16*'00_Inputs'!$B$17 -> 10.128 | D20: Derived — the discharge value in the peak window
A21: SIZING (MODULE 00)
A22: Contract demand (MW) | B22: 10
A23: Night load 00–06 (MW) | B23: 5
A24: Day load 06–17 (MW) | B24: 7
A25: Evening load 17–24 (MW) | B25: 9 | D25: MSEDCL peak-window load — the replacement target
A26: Peak coverage target | B26: 1 | D26: Share of 17–24 h consumption the BESS should serve
A27: SoC min | B27: 0.1 | D27: Lower state-of-charge buffer protecting cell health
A28: SoC max | B28: 0.9 | D28: Usable SoC window = SoC max − SoC min (doc: 10–90% → 80%)
A29: SoH — design | B29: 0.9 | D29: Sizing holds at this State of Health (≈90% after 4,000 cycles)
A30: Container C-rate | B30: 0.25 | D30: 0.25C = 4-h product → 1.25 MW per 5 MWh container
A31: LOSSES — FROM THE BESS REFERENCE DOC
A32: Transformer loss | B32: 0.02
A33: Transmission / cable loss | B33: 0.015
A34: Standby & auxiliary | B34: 0.01 | D34: HVAC, BMS, controls — % of throughput
A35: External efficiency (one way) | B35: =(1-'00_Inputs'!$B$32)*(1-'00_Inputs'!$B$33)*(1-'00_Inputs'!$B$34) -> 0.955647 | D35: Transformer × transmission × auxiliary ≈ 95.6%
A36: Overall system RTE | B36: ='00_Inputs'!$B$12*'00_Inputs'!$B$35^2 -> 0.80366985 | D36: Every 1 MWh bought returns ≈ this much at the meter (doc: ~86%)
A37: FINANCIALS
A38: Capex (₹ Cr per MWh) | B38: 1.1
A39: O&M (% of capex per year) | B39: 0.015
A40: Operating days per year | B40: 330
A41: Battery degradation per year | B41: 0.02
...

Sheet 01_Sizing
A1: MODULE 00 · SIZING
A2: BESS size to replace MSEDCL peak-window (17:00–24:00) consumption
A3: The battery must serve the 7-hour peak AND recharge through contract-demand headroom in the other 17 hours.
A5: RESULTS
A6: Peak energy at 100% coverage (MWh) | C6: =SUM($F$38:$F$61) -> 63 | I6: Σ min(load, contract) over 17–24 h
A7: Recharge headroom available (MWh) | C7: =SUM($H$38:$H$61) -> 63 | I7: Σ min(contract − load, BESS power at target coverage) over non-peak hours
A8: Max feasible coverage | C8: =MIN('00_Inputs'!$B$26,C7*'00_Inputs'!$B$12*'00_Inputs'!$B$35^2/C6) -> 0.80366985 | I8: Coverage whose grid recharge (meter ÷ ext-eff ÷ RTE ÷ ext-eff) fits the headroom
A9: Suggested power (MW) | C9: =CEILING(MAX($F$38:$F$61)*C8,0.5) -> 7.5 | I9: Max BESS output in the peak window, rounded up to 0.5 MW
A10: Energy needed — nameplate (MWh) | C10: =CEILING(C6*C8/'00_Inputs'!$B$35/(('00_Inputs'!$B$28-'00_Inputs'!$B$27)*'00_Inputs'!$B$29),1) -> 74 | I10: Meter demand ÷ external eff ÷ (SoC window × SoH) — doc formula
A11: Container rating (MWh) | C11: ='04_Container'!$C$5 -> 5.0159616 | I11: 5 MWh container from the container build-up sheet
A12: Containers required | C12: =MAX(ROUNDUP(C10/C11,0),ROUNDUP(C9/('00_Inputs'!$B$30*C11),0)) -> 15 | I12: Larger of energy need and C-rate power need (0.25C → 1.25 MW per container)
A13: Installed energy (MWh) | C13: =C12*C11 -> 75.239424 | I13: Feeds dispatch & revenue when the Inputs switch = 1
A14: Duration (h) | C14: =C13/C9 -> 10.031923 | I14: installed, vs the 7-h MSEDCL peak window
A15: Indicative capex (₹ Cr) | C15: =C13*'00_Inputs'!$B$38*1.05 -> 86.901535 | I15: on installed energy, +5% contingency
A16: Feasibility check | C16: =IF('00_Inputs'!$B$26<=C8+0.0001,"OK — target coverage feasible","CHECK — max feasible coverage = "&TEXT(C8,"0%")&". Raise contract demand, shed day load, or add on-site solar.") -> CHECK — max feasible coverage = 80%. Raise contract demand, shed day load, or add on-site solar.
A18: PCS CONFIGURATION — MARKET-AVAILABLE UNITS (1500 V DC CLASS)
A19: PCS unit rating (MW) | C19: 2.5 | I19: Market blocks: 0.25 (string) · 1.25 · 2.5 · 3.45 · 5.0 MW skids
A20: Containers per PCS (block size) | C20: 4 | I20: Reference doc: 1 block = 4 containers + 1 PCS
A21: PCS sizing margin over duty | C21: 0.2 | I21: Doc sizes the inverter at 1.20 × continuous power
A22: Redundant units (N+1 → enter 1) | C22: 0
A23: PCS units required | C23: =MAX(ROUNDUP(C9*(1+C21)/C19,0),ROUNDUP(C12/C20,0))+C22 -> 4 | I23: Larger of the power method and the block (containers ÷ per-PCS) method
A24: PCS installed (MW) | C24: =C23*C19 -> 10
A25: System C-rate (PCS ÷ installed energy) | C25: =C24/C13 -> 0.13290905 | D25: =IF(C25<='00_Inputs'!$B$30,"OK — within the container C-rate","CHECK — above the container C-rate: batteries cap plant power at "&TEXT('00_Inputs'!$B$30*C13,"0.0")&" MW") -> OK — within the container C-rate
A27: CHARGING-CYCLE VALIDATION & ENERGY REALITY — INDIAN (MSEDCL) OPERATING DAY
A28: Usable energy per cycle (MWh) | C28: =C13*(('00_Inputs'!$B$28-'00_Inputs'!$B$27)*'00_Inputs'!$B$29) -> 54.172385 | I28: Installed × SoC window × SoH — doc: usable ≠ installed
A29: Battery-side duty per day (MWh) | C29: =C6*C8/'00_Inputs'!$B$35 -> 52.98107 | I29: Meter demand grossed up by transformer/transmission/auxiliary
A30: Cycles per day implied | C30: =C29/C28 -> 0.9780088 | I30: LFP warranty ≈ 6,000–8,000 cycles: 1/day ≈ 18+ yrs, 2/day ≈ 9–10 yrs
A31: Grid purchase per day (MWh) — energy you PAY for | C31: =C29/'00_Inputs'!$B$12/'00_Inputs'!$B$35 -> 63 | D31: ="solar window (09–17) headroom delivers "&TEXT(SUMPRODUCT(($B$38:$B$61="Solar")*($H$38:$H$61)),"0")&" MWh — balance charges overnight (00–09)" -> solar window (09–17) headroom delivers 24 MWh — balance charges overnight (00–09)
A32: Delivered at meter per day (MWh) — energy that OFFSETS tariff | C32: =C6*C8 -> 50.6312 | I32: Overall system RTE = delivered ÷ purchased ≈ doc's ~86% figure
A33: Cycle verdict | C33: =IF(C30<=1,"ONE daily cycle sufficient — charge solar hours (IEX floor), discharge 17–24 peak. Standard Indian BTM pattern.",IF(C30<=2,"TWO cycles needed — MSEDCL has a single evening peak, so add "&(ROUNDUP(C29/(('00_Inputs'!$B$28-'00_Inputs'!$B$27)*'00_Inputs'!$B$29)/C11,0)-C12)&" containers for one-cycle operation, or run cycle 2 as thin-margin morning arbitrage (dual-peak states like UP/UK support true 2-cycle).","UNDERSIZED — more than 2 cycles/day implied against a single 7-h peak: add containers or cut the coverage target.")) -> ONE daily cycle sufficient — charge solar hours (IEX floor), discharge 17–24 peak. Standard Indian BTM pattern.
A34: Containers if 2 cycles/day were usable | C34: =ROUNDUP(C29/2/(('00_Inputs'!$B$28-'00_Inputs'!$B$27)*'00_Inputs'!$B$29)/C11,0) -> 8 | I34: Needs a second premium window (dual-peak states, RTM stacking) — not available under MSEDCL's single 17–24 peak
A36: 24-HOUR LOAD PROFILE | I36: Blue Override column: type a value to shape an hour individually; leave blank to use the block load.
A37: Hour | B37: Window | C37: Block load (MW) | D37: Override (MW) | E37: Load (MW) | F37: Servable @100% (MW) | G37: Served by BESS (MW) | H37: Recharge headroom (MW) | I37: Notes
A38: 0 | B38: =IF(A38>=17,"Peak",IF(A38>=9,"Solar","Normal")) -> Normal | C38: =IF(A38<6,'00_Inputs'!$B$23,IF(A38<17,'00_Inputs'!$B$24,'00_Inputs'!$B$25)) -> 5 | E38: =IF(D38<>"",D38,C38) -> 5 | F38: =IF(B38="Peak",MIN(E38,'00_Inputs'!$B$22),0) -> 0 | G38: =F38*$C$8 -> 0 | H38: =IF(B38="Peak",0,MIN(MAX('00_Inputs'!$B$22-E38,0),'00_Inputs'!$B$26*MAX($F$38:$F$61))) -> 5
A39: 1 | B39: =IF(A39>=17,"Peak",IF(A39>=9,"Solar","Normal")) -> Normal | C39: =IF(A39<6,'00_Inputs'!$B$23,IF(A39<17,'00_Inputs'!$B$24,'00_Inputs'!$B$25)) -> 5 | E39: =IF(D39<>"",D39,C39) -> 5 | F39: =IF(B39="Peak",MIN(E39,'00_Inputs'!$B$22),0) -> 0 | G39: =F39*$C$8 -> 0 | H39: =IF(B39="Peak",0,MIN(MAX('00_Inputs'!$B$22-E39,0),'00_Inputs'!$B$26*MAX($F$38:$F$61))) -> 5
A40: 2 | B40: =IF(A40>=17,"Peak",IF(A40>=9,"Solar","Normal")) -> Normal | C40: =IF(A40<6,'00_Inputs'!$B$23,IF(A40<17,'00_Inputs'!$B$24,'00_Inputs'!$B$25)) -> 5 | E40: =IF(D40<>"",D40,C40) -> 5 | F40: =IF(B40="Peak",MIN(E40,'00_Inputs'!$B$22),0) -> 0 | G40: =F40*$C$8 -> 0 | H40: =IF(B40="Peak",0,MIN(MAX('00_Inputs'!$B$22-E40,0),'00_Inputs'!$B$26*MAX($F$38:$F$61))) -> 5
A41: 3 | B41: =IF(A41>=17,"Peak",IF(A41>=9,"Solar","Normal")) -> Normal | C41: =IF(A41<6,'00_Inputs'!$B$23,IF(A41<17,'00_Inputs'!$B$24,'00_Inputs'!$B$25)) -> 5 | E41: =IF(D41<>"",D41,C41) -> 5 | F41: =IF(B41="Peak",MIN(E41,'00_Inputs'!$B$22),0) -> 0 | G41: =F41*$C$8 -> 0 | H41: =IF(B41="Peak",0,MIN(MAX('00_Inputs'!$B$22-E41,0),'00_Inputs'!$B$26*MAX($F$38:$F$61))) -> 5
A42: 4 | B42: =IF(A42>=17,"Peak",IF(A42>=9,"Solar","Normal")) -> Normal | C42: =IF(A42<6,'00_Inputs'!$B$23,IF(A42<17,'00_Inputs'!$B$24,'00_Inputs'!$B$25)) -> 5 | E42: =IF(D42<>"",D42,C42) -> 5 | F42: =IF(B42="Peak",MIN(E42,'00_Inputs'!$B$22),0) -> 0 | G42: =F42*$C$8 -> 0 | H42: =IF(B42="Peak",0,MIN(MAX('00_Inputs'!$B$22-E42,0),'00_Inputs'!$B$26*MAX($F$38:$F$61))) -> 5
A43: 5 | B43: =IF(A43>=17,"Peak",IF(A43>=9,"Solar","Normal")) -> Normal | C43: =IF(A43<6,'00_Inputs'!$B$23,IF(A43<17,'00_Inputs'!$B$24,'00_Inputs'!$B$25)) -> 5 | E43: =IF(D43<>"",D43,C43) -> 5 | F43: =IF(B43="Peak",MIN(E43,'00_Inputs'!$B$22),0) -> 0 | G43: =F43*$C$8 -> 0 | H43: =IF(B43="Peak",0,MIN(MAX('00_Inputs'!$B$22-E43,0),'00_Inputs'!$B$26*MAX($F$38:$F$61))) -> 5
A44: 6 | B44: =IF(A44>=17,"Peak",IF(A44>=9,"Solar","Normal")) -> Normal | C44: =IF(A44<6,'00_Inputs'!$B$23,IF(A44<17,'00_Inputs'!$B$24,'00_Inputs'!$B$25)) -> 7 | E44: =IF(D44<>"",D44,C44) -> 7 | F44: =IF(B44="Peak",MIN(E44,'00_Inputs'!$B$22),0) -> 0 | G44: =F44*$C$8 -> 0 | H44: =IF(B44="Peak",0,MIN(MAX('00_Inputs'!$B$22-E44,0),'00_Inputs'!$B$26*MAX($F$38:$F$61))) -> 3
...

Sheet 02_Dispatch
A1: MODULE 01 · DISPATCH
A2: Charge on the exchange, discharge behind the meter against MSEDCL ToD
A3: Charges the cheapest non-peak landed hours — only while landed cost < RTE × peak tariff (marginal profitability) — then discharges through the 17–24 h peak. Single daily cycle: MSEDCL has one evening peak.
A5: DAY RESULT
A6: Deliverable energy target (MWh) | C6: =MIN('00_Inputs'!$B$14,'00_Inputs'!$B$13*7/'00_Inputs'!$B$12) -> 59.659091 | E6: SoC the 7-hour peak window can actually discharge
A7: Charge hours needed | C7: =CEILING(C6/'00_Inputs'!$B$13,1) -> 8
A8: Energy drawn from exchange (MWh) | C8: =SUM($H$21:$H$44) -> 59.659091
A9: Energy delivered in peak (MWh) | C9: =SUM($I$21:$I$44) -> 52.5
A10: Charge cost (₹/day) | C10: =SUM($L$21:$L$44) -> 390698.86 | E10: landed, incl. open access
A11: Avoided tariff value (₹/day) | C11: =SUM($M$21:$M$44) -> 531720
A12: Net saving per day (₹ lakh) | C12: =(C11-C10)/100000 -> 1.4102114
A13: Net saving per year (₹ Cr) | C13: =C12*'00_Inputs'!$B$40/100 -> 4.6536975 | E13: feeds 03_Revenue arbitrage line
A14: Avg charge cost (₹/kWh) | C14: =IF(C8>0,C10/C8/1000,0) -> 6.5488571
A15: Avg discharge value (₹/kWh) | C15: =IF(C9>0,C11/C9/1000,0) -> 10.128
A16: Effective spread after losses (₹/kWh) | C16: =C15-C14/'00_Inputs'!$B$12 -> 2.6861169 | E16: per kWh delivered
A17: End-of-day state of charge | C17: =$J$44/'00_Inputs'!$B$14 -> 0 | E17: ≈0% means nothing bought that could not be sold
A20: Hour | B20: Window | C20: IEX MCP (₹/kWh) | D20: Landed (₹/kWh) | E20: ToD tariff (₹/kWh) | F20: Charge rank | G20: Charge hour? | H20: Charge (MW) | I20: Discharge (MW) | J20: SoC (MWh) | K20: SoC (%) | L20: Charge cost (₹) | M20: Avoided (₹) | N20: Action
A21: 0 | B21: =IF(A21>=17,"Peak",IF(A21>=9,"Solar","Normal")) -> Normal | C21: =INDEX(Prices!$B$2:$D$25,A21+1,'00_Inputs'!$B$7) -> 4.2 | D21: =C21+'00_Inputs'!$B$19 -> 7.85 | E21: ='00_Inputs'!$B$16*IF(B21="Peak",'00_Inputs'!$B$17,IF(B21="Solar",'00_Inputs'!$B$18,1)) -> 8.44 | F21: =IF(B21="Peak","",SUMPRODUCT(($B$21:$B$44<>"Peak")*($D$21:$D$44<D21))+1) -> 14 | G21: =IF(B21="Peak",0,IF(AND(F21<=$C$7,D21<'00_Inputs'!$B$12*'00_Inputs'!$B$20),1,0)) -> 0 | H21: =IF(G21=1,MIN('00_Inputs'!$B$13,$C$6),0) -> 0 | I21: =0 -> 0 | J21: =H21-I21/'00_Inputs'!$B$12 -> 0 | K21: =J21/'00_Inputs'!$B$14 -> 0 | L21: =H21*1000*D21 -> 0 | M21: =I21*1000*E21 -> 0 | N21: =IF(H21>0,"CHARGE",IF(I21>0,"DISCHARGE","—")) -> —
A22: 1 | B22: =IF(A22>=17,"Peak",IF(A22>=9,"Solar","Normal")) -> Normal | C22: =INDEX(Prices!$B$2:$D$25,A22+1,'00_Inputs'!$B$7) -> 3.9 | D22: =C22+'00_Inputs'!$B$19 -> 7.55 | E22: ='00_Inputs'!$B$16*IF(B22="Peak",'00_Inputs'!$B$17,IF(B22="Solar",'00_Inputs'!$B$18,1)) -> 8.44 | F22: =IF(B22="Peak","",SUMPRODUCT(($B$21:$B$44<>"Peak")*($D$21:$D$44<D22))+1) -> 11 | G22: =IF(B22="Peak",0,IF(AND(F22<=$C$7,D22<'00_Inputs'!$B$12*'00_Inputs'!$B$20),1,0)) -> 0 | H22: =IF(G22=1,MIN('00_Inputs'!$B$13,MAX(0,$C$6-SUM($H$21:H21))),0) -> 0 | I22: =IF(B22="Peak",MIN('00_Inputs'!$B$13,J21*'00_Inputs'!$B$12),0) -> 0 | J22: =J21+H22-I22/'00_Inputs'!$B$12 -> 0 | K22: =J22/'00_Inputs'!$B$14 -> 0 | L22: =H22*1000*D22 -> 0 | M22: =I22*1000*E22 -> 0 | N22: =IF(H22>0,"CHARGE",IF(I22>0,"DISCHARGE","—")) -> —
A23: 2 | B23: =IF(A23>=17,"Peak",IF(A23>=9,"Solar","Normal")) -> Normal | C23: =INDEX(Prices!$B$2:$D$25,A23+1,'00_Inputs'!$B$7) -> 3.7 | D23: =C23+'00_Inputs'!$B$19 -> 7.35 | E23: ='00_Inputs'!$B$16*IF(B23="Peak",'00_Inputs'!$B$17,IF(B23="Solar",'00_Inputs'!$B$18,1)) -> 8.44 | F23: =IF(B23="Peak","",SUMPRODUCT(($B$21:$B$44<>"Peak")*($D$21:$D$44<D23))+1) -> 9 | G23: =IF(B23="Peak",0,IF(AND(F23<=$C$7,D23<'00_Inputs'!$B$12*'00_Inputs'!$B$20),1,0)) -> 0 | H23: =IF(G23=1,MIN('00_Inputs'!$B$13,MAX(0,$C$6-SUM($H$21:H22))),0) -> 0 | I23: =IF(B23="Peak",MIN('00_Inputs'!$B$13,J22*'00_Inputs'!$B$12),0) -> 0 | J23: =J22+H23-I23/'00_Inputs'!$B$12 -> 0 | K23: =J23/'00_Inputs'!$B$14 -> 0 | L23: =H23*1000*D23 -> 0 | M23: =I23*1000*E23 -> 0 | N23: =IF(H23>0,"CHARGE",IF(I23>0,"DISCHARGE","—")) -> —
A24: 3 | B24: =IF(A24>=17,"Peak",IF(A24>=9,"Solar","Normal")) -> Normal | C24: =INDEX(Prices!$B$2:$D$25,A24+1,'00_Inputs'!$B$7) -> 3.6 | D24: =C24+'00_Inputs'!$B$19 -> 7.25 | E24: ='00_Inputs'!$B$16*IF(B24="Peak",'00_Inputs'!$B$17,IF(B24="Solar",'00_Inputs'!$B$18,1)) -> 8.44 | F24: =IF(B24="Peak","",SUMPRODUCT(($B$21:$B$44<>"Peak")*($D$21:$D$44<D24))+1) -> 8 | G24: =IF(B24="Peak",0,IF(AND(F24<=$C$7,D24<'00_Inputs'!$B$12*'00_Inputs'!$B$20),1,0)) -> 1 | H24: =IF(G24=1,MIN('00_Inputs'!$B$13,MAX(0,$C$6-SUM($H$21:H23))),0) -> 7.5 | I24: =IF(B24="Peak",MIN('00_Inputs'!$B$13,J23*'00_Inputs'!$B$12),0) -> 0 | J24: =J23+H24-I24/'00_Inputs'!$B$12 -> 7.5 | K24: =J24/'00_Inputs'!$B$14 -> 0.099681784 | L24: =H24*1000*D24 -> 54375 | M24: =I24*1000*E24 -> 0 | N24: =IF(H24>0,"CHARGE",IF(I24>0,"DISCHARGE","—")) -> CHARGE
A25: 4 | B25: =IF(A25>=17,"Peak",IF(A25>=9,"Solar","Normal")) -> Normal | C25: =INDEX(Prices!$B$2:$D$25,A25+1,'00_Inputs'!$B$7) -> 3.5 | D25: =C25+'00_Inputs'!$B$19 -> 7.15 | E25: ='00_Inputs'!$B$16*IF(B25="Peak",'00_Inputs'!$B$17,IF(B25="Solar",'00_Inputs'!$B$18,1)) -> 8.44 | F25: =IF(B25="Peak","",SUMPRODUCT(($B$21:$B$44<>"Peak")*($D$21:$D$44<D25))+1) -> 7 | G25: =IF(B25="Peak",0,IF(AND(F25<=$C$7,D25<'00_Inputs'!$B$12*'00_Inputs'!$B$20),1,0)) -> 1 | H25: =IF(G25=1,MIN('00_Inputs'!$B$13,MAX(0,$C$6-SUM($H$21:H24))),0) -> 7.5 | I25: =IF(B25="Peak",MIN('00_Inputs'!$B$13,J24*'00_Inputs'!$B$12),0) -> 0 | J25: =J24+H25-I25/'00_Inputs'!$B$12 -> 15 | K25: =J25/'00_Inputs'!$B$14 -> 0.19936357 | L25: =H25*1000*D25 -> 53625 | M25: =I25*1000*E25 -> 0 | N25: =IF(H25>0,"CHARGE",IF(I25>0,"DISCHARGE","—")) -> CHARGE
A26: 5 | B26: =IF(A26>=17,"Peak",IF(A26>=9,"Solar","Normal")) -> Normal | C26: =INDEX(Prices!$B$2:$D$25,A26+1,'00_Inputs'!$B$7) -> 3.8 | D26: =C26+'00_Inputs'!$B$19 -> 7.45 | E26: ='00_Inputs'!$B$16*IF(B26="Peak",'00_Inputs'!$B$17,IF(B26="Solar",'00_Inputs'!$B$18,1)) -> 8.44 | F26: =IF(B26="Peak","",SUMPRODUCT(($B$21:$B$44<>"Peak")*($D$21:$D$44<D26))+1) -> 10 | G26: =IF(B26="Peak",0,IF(AND(F26<=$C$7,D26<'00_Inputs'!$B$12*'00_Inputs'!$B$20),1,0)) -> 0 | H26: =IF(G26=1,MIN('00_Inputs'!$B$13,MAX(0,$C$6-SUM($H$21:H25))),0) -> 0 | I26: =IF(B26="Peak",MIN('00_Inputs'!$B$13,J25*'00_Inputs'!$B$12),0) -> 0 | J26: =J25+H26-I26/'00_Inputs'!$B$12 -> 15 | K26: =J26/'00_Inputs'!$B$14 -> 0.19936357 | L26: =H26*1000*D26 -> 0 | M26: =I26*1000*E26 -> 0 | N26: =IF(H26>0,"CHARGE",IF(I26>0,"DISCHARGE","—")) -> —
A27: 6 | B27: =IF(A27>=17,"Peak",IF(A27>=9,"Solar","Normal")) -> Normal | C27: =INDEX(Prices!$B$2:$D$25,A27+1,'00_Inputs'!$B$7) -> 4.6 | D27: =C27+'00_Inputs'!$B$19 -> 8.25 | E27: ='00_Inputs'!$B$16*IF(B27="Peak",'00_Inputs'!$B$17,IF(B27="Solar",'00_Inputs'!$B$18,1)) -> 8.44 | F27: =IF(B27="Peak","",SUMPRODUCT(($B$21:$B$44<>"Peak")*($D$21:$D$44<D27))+1) -> 15 | G27: =IF(B27="Peak",0,IF(AND(F27<=$C$7,D27<'00_Inputs'!$B$12*'00_Inputs'!$B$20),1,0)) -> 0 | H27: =IF(G27=1,MIN('00_Inputs'!$B$13,MAX(0,$C$6-SUM($H$21:H26))),0) -> 0 | I27: =IF(B27="Peak",MIN('00_Inputs'!$B$13,J26*'00_Inputs'!$B$12),0) -> 0 | J27: =J26+H27-I27/'00_Inputs'!$B$12 -> 15 | K27: =J27/'00_Inputs'!$B$14 -> 0.19936357 | L27: =H27*1000*D27 -> 0 | M27: =I27*1000*E27 -> 0 | N27: =IF(H27>0,"CHARGE",IF(I27>0,"DISCHARGE","—")) -> —
A28: 7 | B28: =IF(A28>=17,"Peak",IF(A28>=9,"Solar","Normal")) -> Normal | C28: =INDEX(Prices!$B$2:$D$25,A28+1,'00_Inputs'!$B$7) -> 5.4 | D28: =C28+'00_Inputs'!$B$19 -> 9.05 | E28: ='00_Inputs'!$B$16*IF(B28="Peak",'00_Inputs'!$B$17,IF(B28="Solar",'00_Inputs'!$B$18,1)) -> 8.44 | F28: =IF(B28="Peak","",SUMPRODUCT(($B$21:$B$44<>"Peak")*($D$21:$D$44<D28))+1) -> 17 | G28: =IF(B28="Peak",0,IF(AND(F28<=$C$7,D28<'00_Inputs'!$B$12*'00_Inputs'!$B$20),1,0)) -> 0 | H28: =IF(G28=1,MIN('00_Inputs'!$B$13,MAX(0,$C$6-SUM($H$21:H27))),0) -> 0 | I28: =IF(B28="Peak",MIN('00_Inputs'!$B$13,J27*'00_Inputs'!$B$12),0) -> 0 | J28: =J27+H28-I28/'00_Inputs'!$B$12 -> 15 | K28: =J28/'00_Inputs'!$B$14 -> 0.19936357 | L28: =H28*1000*D28 -> 0 | M28: =I28*1000*E28 -> 0 | N28: =IF(H28>0,"CHARGE",IF(I28>0,"DISCHARGE","—")) -> —
A29: 8 | B29: =IF(A29>=17,"Peak",IF(A29>=9,"Solar","Normal")) -> Normal | C29: =INDEX(Prices!$B$2:$D$25,A29+1,'00_Inputs'!$B$7) -> 5.2 | D29: =C29+'00_Inputs'!$B$19 -> 8.85 | E29: ='00_Inputs'!$B$16*IF(B29="Peak",'00_Inputs'!$B$17,IF(B29="Solar",'00_Inputs'!$B$18,1)) -> 8.44 | F29: =IF(B29="Peak","",SUMPRODUCT(($B$21:$B$44<>"Peak")*($D$21:$D$44<D29))+1) -> 16 | G29: =IF(B29="Peak",0,IF(AND(F29<=$C$7,D29<'00_Inputs'!$B$12*'00_Inputs'!$B$20),1,0)) -> 0 | H29: =IF(G29=1,MIN('00_Inputs'!$B$13,MAX(0,$C$6-SUM($H$21:H28))),0) -> 0 | I29: =IF(B29="Peak",MIN('00_Inputs'!$B$13,J28*'00_Inputs'!$B$12),0) -> 0 | J29: =J28+H29-I29/'00_Inputs'!$B$12 -> 15 | K29: =J29/'00_Inputs'!$B$14 -> 0.19936357 | L29: =H29*1000*D29 -> 0 | M29: =I29*1000*E29 -> 0 | N29: =IF(H29>0,"CHARGE",IF(I29>0,"DISCHARGE","—")) -> —
A30: 9 | B30: =IF(A30>=17,"Peak",IF(A30>=9,"Solar","Normal")) -> Solar | C30: =INDEX(Prices!$B$2:$D$25,A30+1,'00_Inputs'!$B$7) -> 4 | D30: =C30+'00_Inputs'!$B$19 -> 7.65 | E30: ='00_Inputs'!$B$16*IF(B30="Peak",'00_Inputs'!$B$17,IF(B30="Solar",'00_Inputs'!$B$18,1)) -> 7.174 | F30: =IF(B30="Peak","",SUMPRODUCT(($B$21:$B$44<>"Peak")*($D$21:$D$44<D30))+1) -> 12 | G30: =IF(B30="Peak",0,IF(AND(F30<=$C$7,D30<'00_Inputs'!$B$12*'00_Inputs'!$B$20),1,0)) -> 0 | H30: =IF(G30=1,MIN('00_Inputs'!$B$13,MAX(0,$C$6-SUM($H$21:H29))),0) -> 0 | I30: =IF(B30="Peak",MIN('00_Inputs'!$B$13,J29*'00_Inputs'!$B$12),0) -> 0 | J30: =J29+H30-I30/'00_Inputs'!$B$12 -> 15 | K30: =J30/'00_Inputs'!$B$14 -> 0.19936357 | L30: =H30*1000*D30 -> 0 | M30: =I30*1000*E30 -> 0 | N30: =IF(H30>0,"CHARGE",IF(I30>0,"DISCHARGE","—")) -> —
A31: 10 | B31: =IF(A31>=17,"Peak",IF(A31>=9,"Solar","Normal")) -> Solar | C31: =INDEX(Prices!$B$2:$D$25,A31+1,'00_Inputs'!$B$7) -> 3 | D31: =C31+'00_Inputs'!$B$19 -> 6.65 | E31: ='00_Inputs'!$B$16*IF(B31="Peak",'00_Inputs'!$B$17,IF(B31="Solar",'00_Inputs'!$B$18,1)) -> 7.174 | F31: =IF(B31="Peak","",SUMPRODUCT(($B$21:$B$44<>"Peak")*($D$21:$D$44<D31))+1) -> 5 | G31: =IF(B31="Peak",0,IF(AND(F31<=$C$7,D31<'00_Inputs'!$B$12*'00_Inputs'!$B$20),1,0)) -> 1 | H31: =IF(G31=1,MIN('00_Inputs'!$B$13,MAX(0,$C$6-SUM($H$21:H30))),0) -> 7.5 | I31: =IF(B31="Peak",MIN('00_Inputs'!$B$13,J30*'00_Inputs'!$B$12),0) -> 0 | J31: =J30+H31-I31/'00_Inputs'!$B$12 -> 22.5 | K31: =J31/'00_Inputs'!$B$14 -> 0.29904535 | L31: =H31*1000*D31 -> 49875 | M31: =I31*1000*E31 -> 0 | N31: =IF(H31>0,"CHARGE",IF(I31>0,"DISCHARGE","—")) -> CHARGE
A32: 11 | B32: =IF(A32>=17,"Peak",IF(A32>=9,"Solar","Normal")) -> Solar | C32: =INDEX(Prices!$B$2:$D$25,A32+1,'00_Inputs'!$B$7) -> 2.6 | D32: =C32+'00_Inputs'!$B$19 -> 6.25 | E32: ='00_Inputs'!$B$16*IF(B32="Peak",'00_Inputs'!$B$17,IF(B32="Solar",'00_Inputs'!$B$18,1)) -> 7.174 | F32: =IF(B32="Peak","",SUMPRODUCT(($B$21:$B$44<>"Peak")*($D$21:$D$44<D32))+1) -> 3 | G32: =IF(B32="Peak",0,IF(AND(F32<=$C$7,D32<'00_Inputs'!$B$12*'00_Inputs'!$B$20),1,0)) -> 1 | H32: =IF(G32=1,MIN('00_Inputs'!$B$13,MAX(0,$C$6-SUM($H$21:H31))),0) -> 7.5 | I32: =IF(B32="Peak",MIN('00_Inputs'!$B$13,J31*'00_Inputs'!$B$12),0) -> 0 | J32: =J31+H32-I32/'00_Inputs'!$B$12 -> 30 | K32: =J32/'00_Inputs'!$B$14 -> 0.39872714 | L32: =H32*1000*D32 -> 46875 | M32: =I32*1000*E32 -> 0 | N32: =IF(H32>0,"CHARGE",IF(I32>0,"DISCHARGE","—")) -> CHARGE
A33: 12 | B33: =IF(A33>=17,"Peak",IF(A33>=9,"Solar","Normal")) -> Solar | C33: =INDEX(Prices!$B$2:$D$25,A33+1,'00_Inputs'!$B$7) -> 2.4 | D33: =C33+'00_Inputs'!$B$19 -> 6.05 | E33: ='00_Inputs'!$B$16*IF(B33="Peak",'00_Inputs'!$B$17,IF(B33="Solar",'00_Inputs'!$B$18,1)) -> 7.174 | F33: =IF(B33="Peak","",SUMPRODUCT(($B$21:$B$44<>"Peak")*($D$21:$D$44<D33))+1) -> 1 | G33: =IF(B33="Peak",0,IF(AND(F33<=$C$7,D33<'00_Inputs'!$B$12*'00_Inputs'!$B$20),1,0)) -> 1 | H33: =IF(G33=1,MIN('00_Inputs'!$B$13,MAX(0,$C$6-SUM($H$21:H32))),0) -> 7.5 | I33: =IF(B33="Peak",MIN('00_Inputs'!$B$13,J32*'00_Inputs'!$B$12),0) -> 0 | J33: =J32+H33-I33/'00_Inputs'!$B$12 -> 37.5 | K33: =J33/'00_Inputs'!$B$14 -> 0.49840892 | L33: =H33*1000*D33 -> 45375 | M33: =I33*1000*E33 -> 0 | N33: =IF(H33>0,"CHARGE",IF(I33>0,"DISCHARGE","—")) -> CHARGE
... A44: 23 | B44: =IF(A44>=17,"Peak",IF(A44>=9,"Solar","Normal")) -> Peak | C44: =INDEX(Prices!$B$2:$D$25,A44+1,'00_Inputs'!$B$7) -> 5 | D44: =C44+'00_Inputs'!$B$19 -> 8.65 | E44: ='00_Inputs'!$B$16*IF(B44="Peak",'00_Inputs'!$B$17,IF(B44="Solar",'00_Inputs'!$B$18,1)) -> 10.128 | F44: =IF(B44="Peak","",SUMPRODUCT(($B$21:$B$44<>"Peak")*($D$21:$D$44<D44))+1) | G44: =IF(B44="Peak",0,IF(AND(F44<=$C$7,D44<'00_Inputs'!$B$12*'00_Inputs'!$B$20),1,0)) -> 0 | H44: =IF(G44=1,MIN('00_Inputs'!$B$13,MAX(0,$C$6-SUM($H$21:H43))),0) -> 0 | I44: =IF(B44="Peak",MIN('00_Inputs'!$B$13,J43*'00_Inputs'!$B$12),0) -> 7.5 | J44: =J43+H44-I44/'00_Inputs'!$B$12 -> 0 | K44: =J44/'00_Inputs'!$B$14 -> 0 | L44: =H44*1000*D44 -> 0 | M44: =I44*1000*E44 -> 75960 | N44: =IF(H44>0,"CHARGE",IF(I44>0,"DISCHARGE","—")) -> DISCHARGE
A46: Simplification vs the app: the app pairs marginal charge/discharge hours and can add a small night→morning cycle; this sheet charges the N cheapest profitable non-peak hours for the single evening peak. Difference is typically <5%.

Sheet 03_Revenue
A1: MODULE 02 · REVENUE MODEL
A2: The savings case on one slide — value stack, payback, 12-year IRR
A4: HEADLINE
A5: Annual savings, year 1 (₹ Cr) | B5: =C24 -> 7.5171745
A6: Investment (₹ Cr) | B6: ='00_Inputs'!$B$14*'00_Inputs'!$B$38*1.05 -> 86.901535 | D6: capex incl. 5% contingency
A7: Payback year | B7: =IF(N25>=0,"Y"&(COUNTIF($C$25:$N$25,"<0")+1),">12 yrs") -> >12 yrs
A8: Project IRR (12-yr) | B8: =IFERROR(IRR(B24:N24),"n/a") -> -0.014367943
A9: NPV at discount rate (₹ Cr) | B9: =B24+NPV('00_Inputs'!$B$42,C24:N24) -> -44.582159
A11: VALUE STACK — YEAR 1 (₹ Cr / yr)
A12: Exchange arbitrage vs ToD tariff | B12: ='02_Dispatch'!$C$13 -> 4.6536975
A13: Demand charge reduction | B13: ='00_Inputs'!$B$44*'00_Inputs'!$B$45*12/10000000 -> 2.7 | D13: kVA shaved × ₹/kVA/mo × 12
A14: Diesel backup displaced | B14: ='00_Inputs'!$B$46*'00_Inputs'!$B$13*1000*('00_Inputs'!$B$47-'00_Inputs'!$B$16)/10000000 -> 1.467 | D14: DG hours × MW × (DG cost − grid tariff)
A15: Gross savings | B15: =SUM(B12:B14) -> 8.8206975
A16: Less: O&M year 1 | B16: =-B6*'00_Inputs'!$B$39 -> -1.303523
A17: Net savings year 1 | B17: =B15+B16 -> 7.5171745
A19: 12-YEAR CASH FLOW (₹ Cr)
A20: Line | B20: Y0 | C20: Y1 | D20: Y2 | E20: Y3 | F20: Y4 | G20: Y5 | H20: Y6 | I20: Y7 | J20: Y8 | K20: Y9 | L20: Y10 | M20: Y11 | N20: Y12
A21: Arbitrage (degrades with battery) | C21: ='02_Dispatch'!$C$13*(1-'00_Inputs'!$B$41)^(1-1) -> 4.6536975 | D21: ='02_Dispatch'!$C$13*(1-'00_Inputs'!$B$41)^(2-1) -> 4.5606235 | E21: ='02_Dispatch'!$C$13*(1-'00_Inputs'!$B$41)^(3-1) -> 4.4694111 | F21: ='02_Dispatch'!$C$13*(1-'00_Inputs'!$B$41)^(4-1) -> 4.3800229 | G21: ='02_Dispatch'!$C$13*(1-'00_Inputs'!$B$41)^(5-1) -> 4.2924224 | H21: ='02_Dispatch'!$C$13*(1-'00_Inputs'!$B$41)^(6-1) -> 4.206574 | I21: ='02_Dispatch'!$C$13*(1-'00_Inputs'!$B$41)^(7-1) -> 4.1224425 | J21: ='02_Dispatch'!$C$13*(1-'00_Inputs'!$B$41)^(8-1) -> 4.0399936 | K21: ='02_Dispatch'!$C$13*(1-'00_Inputs'!$B$41)^(9-1) -> 3.9591938 | L21: ='02_Dispatch'!$C$13*(1-'00_Inputs'!$B$41)^(10-1) -> 3.8800099 | M21: ='02_Dispatch'!$C$13*(1-'00_Inputs'!$B$41)^(11-1) -> 3.8024097 | N21: ='02_Dispatch'!$C$13*(1-'00_Inputs'!$B$41)^(12-1) -> 3.7263615
A22: Demand charge + DG displacement | C22: =$B$13+$B$14 -> 4.167 | D22: =$B$13+$B$14 -> 4.167 | E22: =$B$13+$B$14 -> 4.167 | F22: =$B$13+$B$14 -> 4.167 | G22: =$B$13+$B$14 -> 4.167 | H22: =$B$13+$B$14 -> 4.167 | I22: =$B$13+$B$14 -> 4.167 | J22: =$B$13+$B$14 -> 4.167 | ... N22: =$B$13+$B$14 -> 4.167
A23: O&M (escalates 5%/yr) | C23: =-$B$6*'00_Inputs'!$B$39*1.05^(1-1) -> -1.303523 | D23: =-$B$6*'00_Inputs'!$B$39*1.05^(2-1) -> -1.3686992 | E23: =-$B$6*'00_Inputs'!$B$39*1.05^(3-1) -> -1.4371341 | F23: =-$B$6*'00_Inputs'!$B$39*1.05^(4-1) -> -1.5089908 | G23: =-$B$6*'00_Inputs'!$B$39*1.05^(5-1) -> -1.5844404 | H23: =-$B$6*'00_Inputs'!$B$39*1.05^(6-1) -> -1.6636624 | I23: =-$B$6*'00_Inputs'!$B$39*1.05^(7-1) -> -1.7468455 | J23: =-$B$6*'00_Inputs'!$B$39*1.05^(8-1) -> -1.8341878 | K23: =-$B$6*'00_Inputs'!$B$39*1.05^(9-1) -> -1.9258972 | L23: =-$B$6*'00_Inputs'!$B$39*1.05^(10-1) -> -2.022192 | M23: =-$B$6*'00_Inputs'!$B$39*1.05^(11-1) -> -2.1233016 | N23: =-$B$6*'00_Inputs'!$B$39*1.05^(12-1) -> -2.2294667
A24: Net cash flow | B24: =-B6 -> -86.901535 | C24: =C21+C22+C23 -> 7.5171745 | D24: =D21+D22+D23 -> 7.3589244 | E24: =E21+E22+E23 -> 7.1992769 | F24: =F21+F22+F23 -> 7.038032 | G24: =G21+G22+G23 -> 6.874982 | H24: =H21+H22+H23 -> 6.7099116 | I24: =I21+I22+I23 -> 6.542597 | J24: =J21+J22+J23 -> 6.3728058 | ... N24: =N21+N22+N23 -> 5.6638948
A25: Cumulative cash | B25: =B24 -> -86.901535 | C25: =B25+C24 -> -79.38436 | D25: =C25+D24 -> -72.025436 | E25: =D25+E24 -> -64.826159 | F25: =E25+F24 -> -57.788127 | G25: =F25+G24 -> -50.913145 | H25: =G25+H24 -> -44.203233 | I25: =H25+I24 -> -37.660636 | J25: =I25+J24 -> -31.287831 | ... N25: =M25+N24 -> -7.5527133
A27: Fixed streams held flat; arbitrage degrades with the battery; O&M escalates 5%/yr — same treatment as the app.

Sheet 04_Container
A1: MODULE 00A · CONTAINER BUILD-UP
A2: 5 MWh BESS container — 314 Ah LFP cell electrical build-up
A3: Source: user's "BESS 5 MWH Container Calculation.xlsx". Edit the blue cell specs / counts and the container rating flows into 01_Sizing.
A5: Container nameplate (MWh) | C5: =H13/1000 -> 5.0159616 | E5: Cells per container | G5: =C10*C11*C12*C13 -> 4992 | I5: Referenced by 01_Sizing to convert energy needed into whole containers.
A7: DESIGN A — 52S1P (LV rack, 12 racks parallel)
A8: Level | B8: Series/Parallel | C8: Nos | D8: Of | E8: Voltage (V) | F8: Capacity (Ah) | G8: Energy (Wh) | H8: Energy (kWh) | I8: Notes
A9: Cell | E9: 3.2 | F9: 314 | G9: =E9*F9 -> 1004.8 | H9: =G9/1000 -> 1.0048 | I9: 3.2 V / 314 Ah LFP — blue inputs
A10: Module | B10: Series | C10: 13 | D10: Cells | E10: =C10*E9 -> 41.6 | F10: =F9 -> 314 | G10: =G9*C10 -> 13062.4 | H10: =G10/1000 -> 13.0624
A11: Pack | B11: Series | C11: 4 | D11: Modules | E11: =C11*E10 -> 166.4 | F11: =F10 -> 314 | G11: =G10*C11 -> 52249.6 | H11: =G11/1000 -> 52.2496
A12: Rack | B12: Series | C12: 8 | D12: Packs | E12: =C12*E11 -> 1331.2 | F12: =F11 -> 314 | G12: =G11*C12 -> 417996.8 | H12: =G12/1000 -> 417.9968 | I12: 1,331 V DC rack, 418 kWh
A13: Container | B13: Parallel | C13: 12 | D13: Racks | E13: =E12 -> 1331.2 | F13: =F12*C13 -> 3768 | G13: =G12*C13 -> 5015961.6 | H13: =G13/1000 -> 5015.9616 | I13: 52S1P — voltage unchanged, Ah adds in parallel
A16: DESIGN B — 104S1P (HV rack, 6 racks parallel) — alternate, same energy
A17: Level | B17: Series/Parallel | C17: Nos | D17: Of | E17: Voltage (V) | F17: Capacity (Ah) | G17: Energy (Wh) | H17: Energy (kWh) | I17: Notes
A18: Module | B18: Series | C18: 13 | D18: Cells | E18: =C18*$E$9 -> 41.6 | F18: =$F$9 -> 314 | G18: =$G$9*C18 -> 13062.4 | H18: =G18/1000 -> 13.0624
A19: Pack | B19: Series | C19: 8 | D19: Modules | E19: =C19*E18 -> 332.8 | F19: =F18 -> 314 | G19: =G18*C19 -> 104499.2 | H19: =G19/1000 -> 104.4992
A20: Rack | B20: Series | C20: 8 | D20: Packs | E20: =C20*E19 -> 2662.4 | F20: =F19 -> 314 | G20: =G19*C20 -> 835993.6 | H20: =G20/1000 -> 835.9936 | I20: 2,662 V DC rack
A21: Container | B21: Parallel | C21: 6 | D21: Racks | E21: =E20 -> 2662.4 | F21: =F20*C21 -> 1884 | G21: =G20*C21 -> 5015961.6 | H21: =G21/1000 -> 5015.9616 | I21: 104S1P — same 5,016 kWh as Design A

Sheet 05_Schedule96
A1: MODULE 01A · 96-BLOCK SCHEDULE
A2: Dispatch converted to 15-minute time blocks — RLDC / SLDC / REMC format
A3: Block 1 = 00:00–00:15 … block 96 = 23:45–24:00. Drawal (charging) positive; behind-the-meter discharge is not an injection schedule. Copy into your REMC portal template.
A5: Block No | B5: Time From | C5: Time To | D5: IEX MCP (₹/kWh) | E5: Charge / exchange drawal (MW) | F5: BTM discharge (MW) | G5: Net BESS schedule (MW) | H5: SoC end of block (%) | I5: Action
A6: 1 | B6: =TEXT(TIME(INT((A6-1)*15/60),MOD((A6-1)*15,60),0),"hh:mm") -> 00:00 | C6: =IF(A6=96,"24:00",TEXT(TIME(INT(A6*15/60),MOD(A6*15,60),0),"hh:mm")) -> 00:15 | D6: =INDEX('02_Dispatch'!$C$21:$C$44,INT((A6-1)/4)+1) -> 4.2 | E6: =INDEX('02_Dispatch'!$H$21:$H$44,INT((A6-1)/4)+1) -> 0 | F6: =INDEX('02_Dispatch'!$I$21:$I$44,INT((A6-1)/4)+1) -> 0 | G6: =E6-F6 -> 0 | H6: =100*(IF(INT((A6-1)/4)=0,0,INDEX('02_Dispatch'!$J$21:$J$44,INT((A6-1)/4)))+(INDEX('02_Dispatch'!$J$21:$J$44,INT((A6-1)/4)+1)-IF(INT((A6-1)/4)=0,0,INDEX('02_Dispatch'!$J$21:$J$44,INT((A6-1)/4))))*(MOD(A6-1,4)+1)/4)/'00_Inputs'!$B$14 -> 0 | I6: =IF(E6>0,"CHARGE",IF(F6>0,"DISCHARGE","—")) -> —
A7: 2 | B7: =TEXT(TIME(INT((A7-1)*15/60),MOD((A7-1)*15,60),0),"hh:mm") -> 00:15 | C7: =IF(A7=96,"24:00",TEXT(TIME(INT(A7*15/60),MOD(A7*15,60),0),"hh:mm")) -> 00:30 | D7: =INDEX('02_Dispatch'!$C$21:$C$44,INT((A7-1)/4)+1) -> 4.2 | E7: =INDEX('02_Dispatch'!$H$21:$H$44,INT((A7-1)/4)+1) -> 0 | F7: =INDEX('02_Dispatch'!$I$21:$I$44,INT((A7-1)/4)+1) -> 0 | G7: =E7-F7 -> 0 | H7: =100*(IF(INT((A7-1)/4)=0,0,INDEX('02_Dispatch'!$J$21:$J$44,INT((A7-1)/4)))+(INDEX('02_Dispatch'!$J$21:$J$44,INT((A7-1)/4)+1)-IF(INT((A7-1)/4)=0,0,INDEX('02_Dispatch'!$J$21:$J$44,INT((A7-1)/4))))*(MOD(A7-1,4)+1)/4)/'00_Inputs'!$B$14 -> 0 | I7: =IF(E7>0,"CHARGE",IF(F7>0,"DISCHARGE","—")) -> —
A8: 3 | B8: =TEXT(TIME(INT((A8-1)*15/60),MOD((A8-1)*15,60),0),"hh:mm") -> 00:30 | C8: =IF(A8=96,"24:00",TEXT(TIME(INT(A8*15/60),MOD(A8*15,60),0),"hh:mm")) -> 00:45 | D8: =INDEX('02_Dispatch'!$C$21:$C$44,INT((A8-1)/4)+1) -> 4.2 | E8: =INDEX('02_Dispatch'!$H$21:$H$44,INT((A8-1)/4)+1) -> 0 | F8: =INDEX('02_Dispatch'!$I$21:$I$44,INT((A8-1)/4)+1) -> 0 | G8: =E8-F8 -> 0 | H8: =100*(IF(INT((A8-1)/4)=0,0,INDEX('02_Dispatch'!$J$21:$J$44,INT((A8-1)/4)))+(INDEX('02_Dispatch'!$J$21:$J$44,INT((A8-1)/4)+1)-IF(INT((A8-1)/4)=0,0,INDEX('02_Dispatch'!$J$21:$J$44,INT((A8-1)/4))))*(MOD(A8-1,4)+1)/4)/'00_Inputs'!$B$14 -> 0 | I8: =IF(E8>0,"CHARGE",IF(F8>0,"DISCHARGE","—")) -> —
A9: 4 | B9: =TEXT(TIME(INT((A9-1)*15/60),MOD((A9-1)*15,60),0),"hh:mm") -> 00:45 | C9: =IF(A9=96,"24:00",TEXT(TIME(INT(A9*15/60),MOD(A9*15,60),0),"hh:mm")) -> 01:00 | D9: =INDEX('02_Dispatch'!$C$21:$C$44,INT((A9-1)/4)+1) -> 4.2 | E9: =INDEX('02_Dispatch'!$H$21:$H$44,INT((A9-1)/4)+1) -> 0 | F9: =INDEX('02_Dispatch'!$I$21:$I$44,INT((A9-1)/4)+1) -> 0 | G9: =E9-F9 -> 0 | H9: =100*(IF(INT((A9-1)/4)=0,0,INDEX('02_Dispatch'!$J$21:$J$44,INT((A9-1)/4)))+(INDEX('02_Dispatch'!$J$21:$J$44,INT((A9-1)/4)+1)-IF(INT((A9-1)/4)=0,0,INDEX('02_Dispatch'!$J$21:$J$44,INT((A9-1)/4))))*(MOD(A9-1,4)+1)/4)/'00_Inputs'!$B$14 -> 0 | I9: =IF(E9>0,"CHARGE",IF(F9>0,"DISCHARGE","—")) -> —
A10: 5 | B10: =TEXT(TIME(INT((A10-1)*15/60),MOD((A10-1)*15,60),0),"hh:mm") -> 01:00 | C10: =IF(A10=96,"24:00",TEXT(TIME(INT(A10*15/60),MOD(A10*15,60),0),"hh:mm")) -> 01:15 | D10: =INDEX('02_Dispatch'!$C$21:$C$44,INT((A10-1)/4)+1) -> 3.9 | E10: =INDEX('02_Dispatch'!$H$21:$H$44,INT((A10-1)/4)+1) -> 0 | F10: =INDEX('02_Dispatch'!$I$21:$I$44,INT((A10-1)/4)+1) -> 0 | G10: =E10-F10 -> 0 | H10: =100*(IF(INT((A10-1)/4)=0,0,INDEX('02_Dispatch'!$J$21:$J$44,INT((A10-1)/4)))+(INDEX('02_Dispatch'!$J$21:$J$44,INT((A10-1)/4)+1)-IF(INT((A10-1)/4)=0,0,INDEX('02_Dispatch'!$J$21:$J$44,INT((A10-1)/4))))*(MOD(A10-1,4)+1)/4)/'00_Inputs'!$B$14 -> 0 | I10: =IF(E10>0,"CHARGE",IF(F10>0,"DISCHARGE","—")) -> —
A11: 6 | B11: =TEXT(TIME(INT((A11-1)*15/60),MOD((A11-1)*15,60),0),"hh:mm") -> 01:15 | C11: =IF(A11=96,"24:00",TEXT(TIME(INT(A11*15/60),MOD(A11*15,60),0),"hh:mm")) -> 01:30 | D11: =INDEX('02_Dispatch'!$C$21:$C$44,INT((A11-1)/4)+1) -> 3.9 | E11: =INDEX('02_Dispatch'!$H$21:$H$44,INT((A11-1)/4)+1) -> 0 | F11: =INDEX('02_Dispatch'!$I$21:$I$44,INT((A11-1)/4)+1) -> 0 | G11: =E11-F11 -> 0 | H11: =100*(IF(INT((A11-1)/4)=0,0,INDEX('02_Dispatch'!$J$21:$J$44,INT((A11-1)/4)))+(INDEX('02_Dispatch'!$J$21:$J$44,INT((A11-1)/4)+1)-IF(INT((A11-1)/4)=0,0,INDEX('02_Dispatch'!$J$21:$J$44,INT((A11-1)/4))))*(MOD(A11-1,4)+1)/4)/'00_Inputs'!$B$14 -> 0 | I11: =IF(E11>0,"CHARGE",IF(F11>0,"DISCHARGE","—")) -> —
A12: 7 | B12: =TEXT(TIME(INT((A12-1)*15/60),MOD((A12-1)*15,60),0),"hh:mm") -> 01:30 | C12: =IF(A12=96,"24:00",TEXT(TIME(INT(A12*15/60),MOD(A12*15,60),0),"hh:mm")) -> 01:45 | D12: =INDEX('02_Dispatch'!$C$21:$C$44,INT((A12-1)/4)+1) -> 3.9 | E12: =INDEX('02_Dispatch'!$H$21:$H$44,INT((A12-1)/4)+1) -> 0 | F12: =INDEX('02_Dispatch'!$I$21:$I$44,INT((A12-1)/4)+1) -> 0 | G12: =E12-F12 -> 0 | H12: =100*(IF(INT((A12-1)/4)=0,0,INDEX('02_Dispatch'!$J$21:$J$44,INT((A12-1)/4)))+(INDEX('02_Dispatch'!$J$21:$J$44,INT((A12-1)/4)+1)-IF(INT((A12-1)/4)=0,0,INDEX('02_Dispatch'!$J$21:$J$44,INT((A12-1)/4))))*(MOD(A12-1,4)+1)/4)/'00_Inputs'!$B$14 -> 0 | I12: =IF(E12>0,"CHARGE",IF(F12>0,"DISCHARGE","—")) -> —
A13: 8 | B13: =TEXT(TIME(INT((A13-1)*15/60),MOD((A13-1)*15,60),0),"hh:mm") -> 01:45 | C13: =IF(A13=96,"24:00",TEXT(TIME(INT(A13*15/60),MOD(A13*15,60),0),"hh:mm")) -> 02:00 | D13: =INDEX('02_Dispatch'!$C$21:$C$44,INT((A13-1)/4)+1) -> 3.9 | E13: =INDEX('02_Dispatch'!$H$21:$H$44,INT((A13-1)/4)+1) -> 0 | F13: =INDEX('02_Dispatch'!$I$21:$I$44,INT((A13-1)/4)+1) -> 0 | G13: =E13-F13 -> 0 | H13: =100*(IF(INT((A13-1)/4)=0,0,INDEX('02_Dispatch'!$J$21:$J$44,INT((A13-1)/4)))+(INDEX('02_Dispatch'!$J$21:$J$44,INT((A13-1)/4)+1)-IF(INT((A13-1)/4)=0,0,INDEX('02_Dispatch'!$J$21:$J$44,INT((A13-1)/4))))*(MOD(A13-1,4)+1)/4)/'00_Inputs'!$B$14 -> 0 | I13: =IF(E13>0,"CHARGE",IF(F13>0,"DISCHARGE","—")) -> —
A14: 9 | B14: =TEXT(TIME(INT((A14-1)*15/60),MOD((A14-1)*15,60),0),"hh:mm") -> 02:00 | C14: =IF(A14=96,"24:00",TEXT(TIME(INT(A14*15/60),MOD(A14*15,60),0),"hh:mm")) -> 02:15 | D14: =INDEX('02_Dispatch'!$C$21:$C$44,INT((A14-1)/4)+1) -> 3.7 | E14: =INDEX('02_Dispatch'!$H$21:$H$44,INT((A14-1)/4)+1) -> 0 | F14: =INDEX('02_Dispatch'!$I$21:$I$44,INT((A14-1)/4)+1) -> 0 | G14: =E14-F14 -> 0 | H14: =100*(IF(INT((A14-1)/4)=0,0,INDEX('02_Dispatch'!$J$21:$J$44,INT((A14-1)/4)))+(INDEX('02_Dispatch'!$J$21:$J$44,INT((A14-1)/4)+1)-IF(INT((A14-1)/4)=0,0,INDEX('02_Dispatch'!$J$21:$J$44,INT((A14-1)/4))))*(MOD(A14-1,4)+1)/4)/'00_Inputs'!$B$14 -> 0 | I14: =IF(E14>0,"CHARGE",IF(F14>0,"DISCHARGE","—")) -> —
A15: 10 | B15: =TEXT(TIME(INT((A15-1)*15/60),MOD((A15-1)*15,60),0),"hh:mm") -> 02:15 | C15: =IF(A15=96,"24:00",TEXT(TIME(INT(A15*15/60),MOD(A15*15,60),0),"hh:mm")) -> 02:30 | D15: =INDEX('02_Dispatch'!$C$21:$C$44,INT((A15-1)/4)+1) -> 3.7 | E15: =INDEX('02_Dispatch'!$H$21:$H$44,INT((A15-1)/4)+1) -> 0 | F15: =INDEX('02_Dispatch'!$I$21:$I$44,INT((A15-1)/4)+1) -> 0 | G15: =E15-F15 -> 0 | H15: =100*(IF(INT((A15-1)/4)=0,0,INDEX('02_Dispatch'!$J$21:$J$44,INT((A15-1)/4)))+(INDEX('02_Dispatch'!$J$21:$J$44,INT((A15-1)/4)+1)-IF(INT((A15-1)/4)=0,0,INDEX('02_Dispatch'!$J$21:$J$44,INT((A15-1)/4))))*(MOD(A15-1,4)+1)/4)/'00_Inputs'!$B$14 -> 0 | I15: =IF(E15>0,"CHARGE",IF(F15>0,"DISCHARGE","—")) -> —
A16: 11 | B16: =TEXT(TIME(INT((A16-1)*15/60),MOD((A16-1)*15,60),0),"hh:mm") -> 02:30 | C16: =IF(A16=96,"24:00",TEXT(TIME(INT(A16*15/60),MOD(A16*15,60),0),"hh:mm")) -> 02:45 | D16: =INDEX('02_Dispatch'!$C$21:$C$44,INT((A16-1)/4)+1) -> 3.7 | E16: =INDEX('02_Dispatch'!$H$21:$H$44,INT((A16-1)/4)+1) -> 0 | F16: =INDEX('02_Dispatch'!$I$21:$I$44,INT((A16-1)/4)+1) -> 0 | G16: =E16-F16 -> 0 | H16: =100*(IF(INT((A16-1)/4)=0,0,INDEX('02_Dispatch'!$J$21:$J$44,INT((A16-1)/4)))+(INDEX('02_Dispatch'!$J$21:$J$44,INT((A16-1)/4)+1)-IF(INT((A16-1)/4)=0,0,INDEX('02_Dispatch'!$J$21:$J$44,INT((A16-1)/4))))*(MOD(A16-1,4)+1)/4)/'00_Inputs'!$B$14 -> 0 | I16: =IF(E16>0,"CHARGE",IF(F16>0,"DISCHARGE","—")) -> —
A17: 12 | B17: =TEXT(TIME(INT((A17-1)*15/60),MOD((A17-1)*15,60),0),"hh:mm") -> 02:45 | C17: =IF(A17=96,"24:00",TEXT(TIME(INT(A17*15/60),MOD(A17*15,60),0),"hh:mm")) -> 03:00 | D17: =INDEX('02_Dispatch'!$C$21:$C$44,INT((A17-1)/4)+1) -> 3.7 | E17: =INDEX('02_Dispatch'!$H$21:$H$44,INT((A17-1)/4)+1) -> 0 | F17: =INDEX('02_Dispatch'!$I$21:$I$44,INT((A17-1)/4)+1) -> 0 | G17: =E17-F17 -> 0 | H17: =100*(IF(INT((A17-1)/4)=0,0,INDEX('02_Dispatch'!$J$21:$J$44,INT((A17-1)/4)))+(INDEX('02_Dispatch'!$J$21:$J$44,INT((A17-1)/4)+1)-IF(INT((A17-1)/4)=0,0,INDEX('02_Dispatch'!$J$21:$J$44,INT((A17-1)/4))))*(MOD(A17-1,4)+1)/4)/'00_Inputs'!$B$14 -> 0 | I17: =IF(E17>0,"CHARGE",IF(F17>0,"DISCHARGE","—")) -> —
... A101: 96 | B101: =TEXT(TIME(INT((A101-1)*15/60),MOD((A101-1)*15,60),0),"hh:mm") -> 23:45 | C101: =IF(A101=96,"24:00",TEXT(TIME(INT(A101*15/60),MOD(A101*15,60),0),"hh:mm")) -> 24:00 | D101: =INDEX('02_Dispatch'!$C$21:$C$44,INT((A101-1)/4)+1) -> 5 | E101: =INDEX('02_Dispatch'!$H$21:$H$44,INT((A101-1)/4)+1) -> 0 | F101: =INDEX('02_Dispatch'!$I$21:$I$44,INT((A101-1)/4)+1) -> 7.5 | G101: =E101-F101 -> -7.5 | H101: =100*(IF(INT((A101-1)/4)=0,0,INDEX('02_Dispatch'!$J$21:$J$44,INT((A101-1)/4)))+(INDEX('02_Dispatch'!$J$21:$J$44,INT((A101-1)/4)+1)-IF(INT((A101-1)/4)=0,0,INDEX('02_Dispatch'!$J$21:$J$44,INT((A101-1)/4))))*(MOD(A101-1,4)+1)/4)/'00_Inputs'!$B$14 -> 0 | I101: =IF(E101>0,"CHARGE",IF(F101>0,"DISCHARGE","—")) -> DISCHARGE
A103: SoC is interpolated linearly inside each hour. MW values repeat across the four blocks of an hour — the dispatch plan is hourly; refine block-wise in RTM if needed.

Sheet Prices
A1: Hour | B1: Typical day (DAM) | C1: Summer high-demand day | D1: Monsoon / flat day
A2: 0 | B2: 4.2 | C2: 5 | D2: 3.8
A3: 1 | B3: 3.9 | C3: 4.6 | D3: 3.6
A4: 2 | B4: 3.7 | C4: 4.4 | D4: 3.5
A5: 3 | B5: 3.6 | C5: 4.3 | D5: 3.4
A6: 4 | B6: 3.5 | C6: 4.4 | D6: 3.4
A7: 5 | B7: 3.8 | C7: 4.8 | D7: 3.6
A8: 6 | B8: 4.6 | C8: 5.8 | D8: 4
A9: 7 | B9: 5.4 | C9: 6.8 | D9: 4.4
A10: 8 | B10: 5.2 | C10: 6.2 | D10: 4.4
A11: 9 | B11: 4 | C11: 4.6 | D11: 4
A12: 10 | B12: 3 | C12: 3.2 | D12: 3.7
A13: 11 | B13: 2.6 | C13: 2.6 | D13: 3.5
... A25: 23 | B25: 5 | C25: 6 | D25: 4.1
A27: Representative IEX day-ahead price shapes (₹/kWh) — hardcoded assumptions, not live market data. Source: PowerLogic BESS app (github.com/jai2k701/powerlogic-bess).
